<?xml version="1.0" ?>
<!-- =================================================================================== -->
<!-- |    This document was autogenerated by xacro from /home/vboxuser/lattebot_ws2/src/pkg01/urdf/ur10e.urdf.xacro | -->
<!-- |    EDITING THIS FILE BY HAND IS NOT RECOMMENDED                                 | -->
<!-- =================================================================================== -->
<robot name="ur10e">
    <!-- Materials -->
    <material name="LightGrey">
        <color rgba="0.7 0.7 0.7 1.0" />
    </material>
    <material name="Blue">
        <color rgba="0.0 0.0 0.8 1.0" />
    </material>
    <material name="Red">
        <color rgba="0.8 0.0 0.0 1.0" />
    </material>
    <!-- Base link -->
    <link name="base_link">
        <visual>
            <geometry>
                <mesh filename="package://pkg01/urdf/meshes/ur10e/visual/base.dae" />
            </geometry>
            <material name="LightGrey" />
        </visual>
        <collision>
            <geometry>
                <mesh filename="package://pkg01/urdf/meshes/ur10e/collision/base.stl" />
            </geometry>
        </collision>
        <inertial>
            <mass value="4.0" />
            <origin rpy="0 0 0" xyz="0 0 0" />
            <inertia ixx="0.00443333156" ixy="0.0" ixz="0.0" iyy="0.00443333156" iyz="0.0" izz="0.0072" />
        </inertial>
    </link>
    <link name="shoulder_link">
        <visual>
            <geometry>
                <mesh filename="package://pkg01/urdf/meshes/ur10e/visual/shoulder.dae" />
            </geometry>
            <material name="LightGrey" />
        </visual>
        <collision>
            <geometry>
                <mesh filename="package://pkg01/urdf/meshes/ur10e/collision/shoulder.stl" />
            </geometry>
        </collision>
        <inertial>
            <mass value="7.778" />
            <origin rpy="0 0 0" xyz="0 0 0" />
            <inertia ixx="0.0314743125" ixy="0.0" ixz="0.0" iyy="0.0314743125" iyz="0.0" izz="0.021875" />
        </inertial>
    </link>
    <link name="upper_arm_link">
        <visual>
            <geometry>
                <mesh filename="package://pkg01/urdf/meshes/ur10e/visual/upperarm.dae" />
            </geometry>
            <material name="LightGrey" />
        </visual>
        <collision>
            <geometry>
                <mesh filename="package://pkg01/urdf/meshes/ur10e/collision/upperarm.stl" />
            </geometry>
        </collision>
        <inertial>
            <mass value="12.93" />
            <origin rpy="0 0 0" xyz="0 0 0.30635" />
            <inertia ixx="0.421753803" ixy="0.0" ixz="0.0" iyy="0.421753803" iyz="0.0" izz="0.036365625" />
        </inertial>
    </link>
    <link name="forearm_link">
        <visual>
            <geometry>
                <mesh filename="package://pkg01/urdf/meshes/ur10e/visual/forearm.dae" />
            </geometry>
            <material name="LightGrey" />
        </visual>
        <collision>
            <geometry>
                <mesh filename="package://pkg01/urdf/meshes/ur10e/collision/forearm.stl" />
            </geometry>
        </collision>
        <inertial>
            <mass value="3.87" />
            <origin rpy="0 0 0" xyz="0 0 0.285775" />
            <inertia ixx="0.111172755" ixy="0.0" ixz="0.0" iyy="0.111172755" iyz="0.0" izz="0.010884375" />
        </inertial>
    </link>
    <link name="wrist_1_link">
        <visual>
            <geometry>
                <mesh filename="package://pkg01/urdf/meshes/ur10e/visual/wrist1.dae" />
            </geometry>
            <material name="LightGrey" />
        </visual>
        <collision>
            <geometry>
                <mesh filename="package://pkg01/urdf/meshes/ur10e/collision/wrist1.stl" />
            </geometry>
        </collision>
        <inertial>
            <mass value="1.96" />
            <origin rpy="0 0 0" xyz="0 0 0" />
            <inertia ixx="0.0051082479" ixy="0.0" ixz="0.0" iyy="0.0051082479" iyz="0.0" izz="0.0055125" />
        </inertial>
    </link>
    <link name="wrist_2_link">
        <visual>
            <geometry>
                <mesh filename="package://pkg01/urdf/meshes/ur10e/visual/wrist2.dae" />
            </geometry>
            <material name="LightGrey" />
        </visual>
        <collision>
            <geometry>
                <mesh filename="package://pkg01/urdf/meshes/ur10e/collision/wrist2.stl" />
            </geometry>
        </collision>
        <inertial>
            <mass value="1.96" />
            <origin rpy="0 0 0" xyz="0 0 0" />
            <inertia ixx="0.0051082479" ixy="0.0" ixz="0.0" iyy="0.0051082479" iyz="0.0" izz="0.0055125" />
        </inertial>
    </link>
    <link name="wrist_3_link">
        <visual>
            <geometry>
                <mesh filename="package://pkg01/urdf/meshes/ur10e/visual/wrist3.dae" />
            </geometry>
            <material name="LightGrey" />
        </visual>
        <collision>
            <geometry>
                <mesh filename="package://pkg01/urdf/meshes/ur10e/collision/wrist3.stl" />
            </geometry>
        </collision>
        <inertial>
            <mass value="0.202" />
            <origin rpy="0 0 0" xyz="0.0 0.0 -0.025" />
            <inertia ixx="0.000526462289" ixy="0.0" ixz="0.0" iyy="0.000526462289" iyz="0.0" izz="0.000568125" />
        </inertial>
    </link>
    <link name="ee_link">
        <collision>
            <geometry>
                <box size="0.01 0.01 0.01" />
            </geometry>
            <origin rpy="0 0 0" xyz="-0.01 0 0" />
        </collision>
        <inertial>
            <mass value="0.1" />
            <origin xyz="0 0 0" rpy="0 0 0" />
            <inertia ixx="0.03" iyy="0.03" izz="0.03" ixy="0.0" ixz="0.0" iyz="0.0" />
        </inertial>
    </link>
    <link name="tool0" />
    <link name="flange" />
    <!-- Shoulder link -->
    <joint name="shoulder_pan_joint" type="revolute">
        <parent link="base_link" />
        <child link="shoulder_link" />
        <origin rpy="0.0 0.0 0.0" xyz="0.0 0.0 0.1807" />
        <axis xyz="0 0 1" />
        <limit effort="330.0" lower="-6.283185307179586" upper="6.283185307179586" velocity="2.16" />
        <dynamics damping="0.0" friction="0.0" />
    </joint>
    <!-- Upper arm link -->
    <joint name="shoulder_lift_joint" type="revolute">
        <parent link="shoulder_link" />
        <child link="upper_arm_link" />
        <origin rpy="0.0 0.0 0.0" xyz="0.0 0.17415 0.0" />
        <axis xyz="0 1 0" />
        <limit effort="330.0" lower="-3.141592653589793" upper="3.141592653589793" velocity="2.16" />
        <dynamics damping="0.0" friction="0.0" />
    </joint>
    <!-- Forearm link -->
    <joint name="elbow_joint" type="revolute">
        <parent link="upper_arm_link" />
        <child link="forearm_link" />
        <origin rpy="0.0 0.0 0.0" xyz="0.0 -0.1365 0.6127" />
        <axis xyz="0 1 0" />
        <limit effort="150.0" lower="-3.141592653589793" upper="3.141592653589793" velocity="3.15" />
        <dynamics damping="0.0" friction="0.0" />
    </joint>
    <!-- Wrist 1 link -->
    <joint name="wrist_1_joint" type="revolute">
        <parent link="forearm_link" />
        <child link="wrist_1_link" />
        <origin rpy="0.0 0.0 0.0" xyz="0.0 0.0 0.57155" />
        <axis xyz="0 1 0" />
        <limit effort="54.0" lower="-6.283185307179586" upper="6.283185307179586" velocity="3.2" />
        <dynamics damping="0.0" friction="0.0" />
    </joint>
    <!-- Wrist 2 link -->
    <joint name="wrist_2_joint" type="revolute">
        <parent link="wrist_1_link" />
        <child link="wrist_2_link" />
        <origin rpy="0.0 0.0 0.0" xyz="0.0 0.1365 0.0" />
        <axis xyz="0 0 1" />
        <limit effort="54.0" lower="-6.283185307179586" upper="6.283185307179586" velocity="3.2" />
        <dynamics damping="0.0" friction="0.0" />
    </joint>
    <!-- Wrist 3 link -->
    <joint name="wrist_3_joint" type="revolute">
        <parent link="wrist_2_link" />
        <child link="wrist_3_link" />
        <origin rpy="0.0 0.0 0.0" xyz="0.0 0.0 0.11985" />
        <axis xyz="0 1 0" />
        <limit effort="54.0" lower="-6.283185307179586" upper="6.283185307179586" velocity="3.2" />
        <dynamics damping="0.0" friction="0.0" />
    </joint>
    <!-- End effector frame -->
    <joint name="ee_fixed_joint" type="fixed">
        <parent link="wrist_3_link" />
        <child link="ee_link" />
        <origin rpy="0.0 0.0 0.0" xyz="0.0 0.11655 0.0" />
    </joint>
    <!-- Tool frame -->
    <joint name="wrist_3_link-tool0_fixed_joint" type="fixed">
        <origin rpy="0 0 0" xyz="0 0.11655 0" />
        <parent link="wrist_3_link" />
        <child link="tool0" />
    </joint>
    <!-- ROS-Industrial 'flange' frame: attachment point for EEF models -->
    <joint name="tool0-flange_fixed_joint" type="fixed">
        <origin rpy="0 0 0" xyz="0 0 0" />
        <parent link="tool0" />
        <child link="flange" />
    </joint>
    <!-- Material for platform -->
    <material name="DarkGrey">
        <color rgba="0.3 0.3 0.3 1.0" />
    </material>
    <!-- Fixed world link (ground reference) -->
    <link name="world_platform">
        <inertial>
            <mass value="0.001" />
            <origin rpy="0 0 0" xyz="0 0 0" />
            <inertia ixx="0.001" ixy="0.0" ixz="0.0" iyy="0.001" iyz="0.0" izz="0.001" />
        </inertial>
    </link>
    <!-- Platform base link (moves along rail) -->
    <link name="platform_base">
        <visual>
            <geometry>
                <box size="1.0 0.8 0.15" />
            </geometry>
            <origin rpy="0 0 0" xyz="0 0 0.075" />
            <material name="DarkGrey" />
        </visual>
        <collision>
            <geometry>
                <box size="1.0 0.8 0.15" />
            </geometry>
            <origin rpy="0 0 0" xyz="0 0 0.075" />
        </collision>
        <inertial>
            <mass value="50.0" />
            <origin rpy="0 0 0" xyz="0 0 0.075" />
            <inertia ixx="2.7604166666666665" ixy="0.0" ixz="0.0" iyy="4.260416666666666" iyz="0.0" izz="6.833333333333333" />
        </inertial>
    </link>
    <link name="front_left_wheel">
        <visual>
            <geometry>
                <cylinder length="0.05" radius="0.1" />
            </geometry>
            <origin rpy="1.5707963267948966 0 0" xyz="0 0 0" />
            <material name="Black">
                <color rgba="0.1 0.1 0.1 1.0" />
            </material>
        </visual>
        <collision>
            <geometry>
                <cylinder length="0.05" radius="0.1" />
            </geometry>
            <origin rpy="1.5707963267948966 0 0" xyz="0 0 0" />
        </collision>
        <inertial>
            <mass value="2.0" />
            <origin rpy="1.5707963267948966 0 0" xyz="0 0 0" />
            <inertia ixx="0.005416666666666668" ixy="0.0" ixz="0.0" iyy="0.005416666666666668" iyz="0.0" izz="0.010000000000000002" />
        </inertial>
    </link>
    <joint name="front_left_wheel_joint" type="fixed">
        <parent link="platform_base" />
        <child link="front_left_wheel" />
        <origin rpy="0 0 0" xyz="0.4 0.35 0.02500000000000001" />
    </joint>
    <gazebo reference="front_left_wheel">
        <material>Gazebo/Black</material>
        <mu1>1.0</mu1>
        <mu2>1.0</mu2>
        <plugin name="gazebo_ros_control" filename="libgazebo_ros_control.so">
            <robotNamespace>/</robotNamespace>
        </plugin>
    </gazebo>
    <link name="front_right_wheel">
        <visual>
            <geometry>
                <cylinder length="0.05" radius="0.1" />
            </geometry>
            <origin rpy="1.5707963267948966 0 0" xyz="0 0 0" />
            <material name="Black">
                <color rgba="0.1 0.1 0.1 1.0" />
            </material>
        </visual>
        <collision>
            <geometry>
                <cylinder length="0.05" radius="0.1" />
            </geometry>
            <origin rpy="1.5707963267948966 0 0" xyz="0 0 0" />
        </collision>
        <inertial>
            <mass value="2.0" />
            <origin rpy="1.5707963267948966 0 0" xyz="0 0 0" />
            <inertia ixx="0.005416666666666668" ixy="0.0" ixz="0.0" iyy="0.005416666666666668" iyz="0.0" izz="0.010000000000000002" />
        </inertial>
    </link>
    <joint name="front_right_wheel_joint" type="fixed">
        <parent link="platform_base" />
        <child link="front_right_wheel" />
        <origin rpy="0 0 0" xyz="0.4 -0.35 0.02500000000000001" />
    </joint>
    <gazebo reference="front_right_wheel">
        <material>Gazebo/Black</material>
        <mu1>1.0</mu1>
        <mu2>1.0</mu2>
    </gazebo>
    <link name="rear_left_wheel">
        <visual>
            <geometry>
                <cylinder length="0.05" radius="0.1" />
            </geometry>
            <origin rpy="1.5707963267948966 0 0" xyz="0 0 0" />
            <material name="Black">
                <color rgba="0.1 0.1 0.1 1.0" />
            </material>
        </visual>
        <collision>
            <geometry>
                <cylinder length="0.05" radius="0.1" />
            </geometry>
            <origin rpy="1.5707963267948966 0 0" xyz="0 0 0" />
        </collision>
        <inertial>
            <mass value="2.0" />
            <origin rpy="1.5707963267948966 0 0" xyz="0 0 0" />
            <inertia ixx="0.005416666666666668" ixy="0.0" ixz="0.0" iyy="0.005416666666666668" iyz="0.0" izz="0.010000000000000002" />
        </inertial>
    </link>
    <joint name="rear_left_wheel_joint" type="fixed">
        <parent link="platform_base" />
        <child link="rear_left_wheel" />
        <origin rpy="0 0 0" xyz="-0.4 0.35 0.02500000000000001" />
    </joint>
    <gazebo reference="rear_left_wheel">
        <material>Gazebo/Black</material>
        <mu1>1.0</mu1>
        <mu2>1.0</mu2>
    </gazebo>
    <link name="rear_right_wheel">
        <visual>
            <geometry>
                <cylinder length="0.05" radius="0.1" />
            </geometry>
            <origin rpy="1.5707963267948966 0 0" xyz="0 0 0" />
            <material name="Black">
                <color rgba="0.1 0.1 0.1 1.0" />
            </material>
        </visual>
        <collision>
            <geometry>
                <cylinder length="0.05" radius="0.1" />
            </geometry>
            <origin rpy="1.5707963267948966 0 0" xyz="0 0 0" />
        </collision>
        <inertial>
            <mass value="2.0" />
            <origin rpy="1.5707963267948966 0 0" xyz="0 0 0" />
            <inertia ixx="0.005416666666666668" ixy="0.0" ixz="0.0" iyy="0.005416666666666668" iyz="0.0" izz="0.010000000000000002" />
        </inertial>
    </link>
    <joint name="rear_right_wheel_joint" type="fixed">
        <parent link="platform_base" />
        <child link="rear_right_wheel" />
        <origin rpy="0 0 0" xyz="-0.4 -0.35 0.02500000000000001" />
    </joint>
    <gazebo reference="rear_right_wheel">
        <material>Gazebo/Black</material>
        <mu1>1.0</mu1>
        <mu2>1.0</mu2>
    </gazebo>
    <!-- Prismatic joint for linear motion (0 to 10 meters along X axis) -->
    <joint name="platform_joint" type="prismatic">
        <parent link="world_platform" />
        <child link="platform_base" />
        <origin rpy="0 0 0" xyz="0 0 0" />
        <axis xyz="1 0 0" />
        <!-- Motion along X axis -->
        <limit effort="1000.0" lower="0.0" upper="10.0" velocity="1.0" />
        <dynamics damping="50.0" friction="10.0" />
    </joint>
    <!-- Robot mounting plate on top of platform -->
    <link name="robot_mount">
        <visual>
            <geometry>
                <cylinder length="0.05" radius="0.2" />
            </geometry>
            <origin rpy="0 0 0" xyz="0 0 0.025" />
            <material name="LightGrey">
                <color rgba="0.7 0.7 0.7 1.0" />
            </material>
        </visual>
        <collision>
            <geometry>
                <cylinder length="0.05" radius="0.2" />
            </geometry>
            <origin rpy="0 0 0" xyz="0 0 0.025" />
        </collision>
        <inertial>
            <mass value="5.0" />
            <origin rpy="0 0 0" xyz="0 0 0.025" />
            <inertia ixx="0.0208" ixy="0.0" ixz="0.0" iyy="0.0208" iyz="0.0" izz="0.02" />
        </inertial>
    </link>
    <!-- Fixed joint connecting platform to robot mount -->
    <joint name="platform_to_mount" type="fixed">
        <parent link="platform_base" />
        <child link="robot_mount" />
        <origin rpy="0 0 0" xyz="0 0 0.15" />
    </joint>
    <!-- Gazebo properties -->
    <gazebo reference="world_platform">
        <static>true</static>
    </gazebo>
    <gazebo reference="platform_base">
        <material>Gazebo/DarkGrey</material>
        <mu1>0.8</mu1>
        <mu2>0.8</mu2>
    </gazebo>
    <gazebo reference="robot_mount">
        <material>Gazebo/Grey</material>
    </gazebo>
    <!-- Transmission for the prismatic joint -->
    <transmission name="platform_trans">
        <type>transmission_interface/SimpleTransmission</type>
        <joint name="platform_joint">
            <hardwareInterface>hardware_interface/PositionJointInterface</hardwareInterface>
        </joint>
        <actuator name="platform_motor">
            <mechanicalReduction>1</mechanicalReduction>
            <hardwareInterface>hardware_interface/EffortJointInterface</hardwareInterface>
        </actuator>
    </transmission>
    <!-- Connect robot base to platform mount -->
    <joint name="robot_mount_to_base" type="fixed">
        <origin rpy="0 0 0" xyz="0 0 0.05" />
        <parent link="robot_mount" />
        <child link="base_link" />
    </joint>
    <!-- Simple Gripper Macro for Pick and Place Operations -->
    <!-- Can be attached to UR10e tool0/flange -->
    <!-- Materials -->
    <material name="gripper_gray">
        <color rgba="0.5 0.5 0.5 1.0" />
    </material>
    <material name="gripper_dark">
        <color rgba="0.3 0.3 0.3 1.0" />
    </material>
    <material name="gripper_blue">
        <color rgba="0.2 0.4 0.8 1.0" />
    </material>
    <!-- Base Link (mounts to robot tool flange) -->
    <link name="gripper_base_link">
        <visual>
            <origin rpy="0 0 0" xyz="0 0 0.025" />
            <geometry>
                <cylinder length="0.05" radius="0.04" />
            </geometry>
            <material name="gripper_gray" />
        </visual>
        <collision>
            <origin rpy="0 0 0" xyz="0 0 0.025" />
            <geometry>
                <cylinder length="0.05" radius="0.04" />
            </geometry>
        </collision>
        <inertial>
            <origin rpy="0 0 0" xyz="0 0 0.025" />
            <mass value="0.3" />
            <inertia ixx="0.0001" ixy="0.0" ixz="0.0" iyy="0.0001" iyz="0.0" izz="0.0001" />
        </inertial>
    </link>
    <!-- Palm Link (connection point for fingers) -->
    <link name="gripper_palm">
        <visual>
            <origin rpy="0 0 0" xyz="0 0 0.03" />
            <geometry>
                <box size="0.06 0.08 0.02" />
            </geometry>
            <material name="gripper_blue" />
        </visual>
        <collision>
            <origin rpy="0 0 0" xyz="0 0 0.03" />
            <geometry>
                <box size="0.06 0.08 0.02" />
            </geometry>
        </collision>
        <inertial>
            <origin rpy="0 0 0" xyz="0 0 0.03" />
            <mass value="0.15" />
            <inertia ixx="0.00005" ixy="0.0" ixz="0.0" iyy="0.00005" iyz="0.0" izz="0.00005" />
        </inertial>
    </link>
    <!-- Left Finger -->
    <link name="left_finger">
        <visual>
            <origin rpy="0 0 0" xyz="0 0 0.045" />
            <geometry>
                <box size="0.015 0.025 0.09" />
            </geometry>
            <material name="gripper_dark" />
        </visual>
        <collision>
            <origin rpy="0 0 0" xyz="0 0 0.045" />
            <geometry>
                <box size="0.015 0.025 0.09" />
            </geometry>
        </collision>
        <inertial>
            <origin rpy="0 0 0" xyz="0 0 0.045" />
            <mass value="0.03" />
            <inertia ixx="0.00001" ixy="0.0" ixz="0.0" iyy="0.00001" iyz="0.0" izz="0.00001" />
        </inertial>
    </link>
    <!-- Right Finger -->
    <link name="right_finger">
        <visual>
            <origin rpy="0 0 0" xyz="0 0 0.045" />
            <geometry>
                <box size="0.015 0.025 0.09" />
            </geometry>
            <material name="gripper_dark" />
        </visual>
        <collision>
            <origin rpy="0 0 0" xyz="0 0 0.045" />
            <geometry>
                <box size="0.015 0.025 0.09" />
            </geometry>
        </collision>
        <inertial>
            <origin rpy="0 0 0" xyz="0 0 0.045" />
            <mass value="0.03" />
            <inertia ixx="0.00001" ixy="0.0" ixz="0.0" iyy="0.00001" iyz="0.0" izz="0.00001" />
        </inertial>
    </link>
    <!-- Gripper Tip Link (virtual link for grasping point) -->
    <link name="gripper_tip">
        <visual>
            <origin rpy="0 0 0" xyz="0 0 0" />
            <geometry>
                <sphere radius="0.005" />
            </geometry>
            <material name="gripper_blue" />
        </visual>
    </link>
    <!-- Joint: Base to Palm -->
    <joint name="base_to_palm_joint" type="fixed">
        <parent link="gripper_base_link" />
        <child link="gripper_palm" />
        <origin rpy="0 0 0" xyz="0 0 0.05" />
    </joint>
    <!-- Joint: Left Finger (Prismatic - opens/closes) -->
    <!-- Finger width = 25mm, so half-width = 12.5mm -->
    <!-- Origin at palm edge (40mm/2 = 20mm) minus finger half-width (12.5mm) = 7.5mm -->
    <!-- Lower limit (closed): fingers meet at center without overlap -->
    <!-- Upper limit (open): 25mm travel = 50mm total grip width -->
    <joint name="left_finger_joint" type="prismatic">
        <parent link="gripper_palm" />
        <child link="left_finger" />
        <origin rpy="0 0 0" xyz="0 0.0125 0.04" />
        <axis xyz="0 1 0" />
        <limit effort="100" lower="-0.0125" upper="0.025" velocity="0.5" />
        <dynamics damping="1.0" friction="0.5" />
    </joint>
    <!-- Joint: Right Finger (Prismatic - opens/closes) -->
    <!-- Mirrors left finger motion to maintain symmetric gripping -->
    <joint name="right_finger_joint" type="prismatic">
        <parent link="gripper_palm" />
        <child link="right_finger" />
        <origin rpy="0 0 0" xyz="0 -0.0125 0.04" />
        <axis xyz="0 -1 0" />
        <limit effort="100" lower="-0.0125" upper="0.025" velocity="0.5" />
        <dynamics damping="1.0" friction="0.5" />
    </joint>
    <!-- Joint: Palm to Gripper Tip (fixed, for reference point) -->
    <joint name="palm_to_tip_joint" type="fixed">
        <parent link="gripper_palm" />
        <child link="gripper_tip" />
        <origin rpy="0 0 0" xyz="0 0 0.13" />
    </joint>
    <!-- Gazebo-specific configurations -->
    <gazebo reference="gripper_base_link">
        <material>Gazebo/Grey</material>
        <mu1>0.5</mu1>
        <mu2>0.5</mu2>
    </gazebo>
    <gazebo reference="gripper_palm">
        <material>Gazebo/Blue</material>
        <mu1>0.8</mu1>
        <mu2>0.8</mu2>
    </gazebo>
    <gazebo reference="left_finger">
        <material>Gazebo/DarkGrey</material>
        <mu1>2.0</mu1>
        <mu2>2.0</mu2>
        <kp>1000000.0</kp>
        <kd>100.0</kd>
        <minDepth>0.001</minDepth>
        <maxVel>0.1</maxVel>
    </gazebo>
    <gazebo reference="right_finger">
        <material>Gazebo/DarkGrey</material>
        <mu1>2.0</mu1>
        <mu2>2.0</mu2>
        <kp>1000000.0</kp>
        <kd>100.0</kd>
        <minDepth>0.001</minDepth>
        <maxVel>0.1</maxVel>
    </gazebo>
    <!-- Transmission for left finger (for ros_control) -->
    <transmission name="left_finger_trans">
        <type>transmission_interface/SimpleTransmission</type>
        <joint name="left_finger_joint">
            <hardwareInterface>hardware_interface/EffortJointInterface</hardwareInterface>
        </joint>
        <actuator name="left_finger_motor">
            <mechanicalReduction>1</mechanicalReduction>
            <hardwareInterface>hardware_interface/EffortJointInterface</hardwareInterface>
        </actuator>
    </transmission>
    <!-- Transmission for right finger (for ros_control) -->
    <transmission name="right_finger_trans">
        <type>transmission_interface/SimpleTransmission</type>
        <joint name="right_finger_joint">
            <hardwareInterface>hardware_interface/EffortJointInterface</hardwareInterface>
        </joint>
        <actuator name="right_finger_motor">
            <mechanicalReduction>1</mechanicalReduction>
            <hardwareInterface>hardware_interface/EffortJointInterface</hardwareInterface>
        </actuator>
    </transmission>
    <!-- Gazebo Mimic Joint Plugin (makes right finger mirror left finger motion) -->
    <gazebo>
        <plugin filename="libroboticsgroup_gazebo_mimic_joint_plugin.so" name="mimic_joint_plugin">
            <joint>left_finger_joint</joint>
            <mimicJoint>right_finger_joint</mimicJoint>
            <multiplier>1.0</multiplier>
            <offset>0.0</offset>
            <maxEffort>100</maxEffort>
            <robotNamespace>/</robotNamespace>
        </plugin>
    </gazebo>
    <joint name="gripper_mount" type="fixed">
        <parent link="flange" />
        <child link="gripper_base_link" />
        <origin rpy="-1.5707963267948966 0 0" xyz="0 0 0" />
    </joint>
    <!-- Gazebo plugin for ROS Control -->
    <gazebo>
        <plugin filename="libgazebo_ros_control.so" name="gazebo_ros_control">
            <robotNamespace>/ur10e_robot</robotNamespace>
            <robotSimType>gazebo_ros_control/DefaultRobotHWSim</robotSimType>
        </plugin>
    </gazebo>
    <!-- Add transmission elements for each joint -->
    <transmission name="shoulder_pan_trans">
        <type>transmission_interface/SimpleTransmission</type>
        <joint name="shoulder_pan_joint">
            <hardwareInterface>hardware_interface/PositionJointInterface</hardwareInterface>
        </joint>
        <actuator name="shoulder_pan_motor">
            <mechanicalReduction>1</mechanicalReduction>
            <hardwareInterface>hardware_interface/EffortJointInterface</hardwareInterface>
        </actuator>
    </transmission>
    <transmission name="shoulder_lift_trans">
        <type>transmission_interface/SimpleTransmission</type>
        <joint name="shoulder_lift_joint">
            <hardwareInterface>hardware_interface/PositionJointInterface</hardwareInterface>
        </joint>
        <actuator name="shoulder_lift_motor">
            <mechanicalReduction>1</mechanicalReduction>
            <hardwareInterface>hardware_interface/EffortJointInterface</hardwareInterface>
        </actuator>
    </transmission>
    <transmission name="elbow_trans">
        <type>transmission_interface/SimpleTransmission</type>
        <joint name="elbow_joint">
            <hardwareInterface>hardware_interface/PositionJointInterface</hardwareInterface>
        </joint>
        <actuator name="elbow_motor">
            <mechanicalReduction>1</mechanicalReduction>
            <hardwareInterface>hardware_interface/EffortJointInterface</hardwareInterface>
        </actuator>
    </transmission>
    <transmission name="wrist_1_trans">
        <type>transmission_interface/SimpleTransmission</type>
        <joint name="wrist_1_joint">
            <hardwareInterface>hardware_interface/PositionJointInterface</hardwareInterface>
        </joint>
        <actuator name="wrist_1_motor">
            <mechanicalReduction>1</mechanicalReduction>
            <hardwareInterface>hardware_interface/EffortJointInterface</hardwareInterface>
        </actuator>
    </transmission>
    <transmission name="wrist_2_trans">
        <type>transmission_interface/SimpleTransmission</type>
        <joint name="wrist_2_joint">
            <hardwareInterface>hardware_interface/PositionJointInterface</hardwareInterface>
        </joint>
        <actuator name="wrist_2_motor">
            <mechanicalReduction>1</mechanicalReduction>
            <hardwareInterface>hardware_interface/EffortJointInterface</hardwareInterface>
        </actuator>
    </transmission>
    <transmission name="wrist_3_trans">
        <type>transmission_interface/SimpleTransmission</type>
        <joint name="wrist_3_joint">
            <hardwareInterface>hardware_interface/PositionJointInterface</hardwareInterface>
        </joint>
        <actuator name="wrist_3_motor">
            <mechanicalReduction>1</mechanicalReduction>
            <hardwareInterface>hardware_interface/EffortJointInterface</hardwareInterface>
        </actuator>
    </transmission>
</robot>

